Workbook

Sheet Sheet1
C1: Exercise | H1: Tests Ex 1 | M1: Tests Ex 2 | R1: Tests Ex 3 | W1: Tests Ex 4 | AB1: Tests Ex 5
A2: Matricola | B2: SCORE | C2: 1 | D2: 2 | E2: 3 | F2: 4 | G2: 5 | H2: 1 | I2: 2 | J2: 3 | K2: 4 | L2: 5 | M2: 1 | N2: 2 | O2: 3 | P2: 4 | Q2: 5 | R2: 1 | S2: 2 | T2: 3 | U2: 4 | V2: 5 | W2: 1 | X2: 2 | Y2: 3 | Z2: 4 | AA2: 5 | AB2: 1 | AC2: 2 | AD2: 3 | AE2: 4 | AF2: 5
A3: 1992383 | B3: =(15*C3 + 25*D3 + 25*E3 + 15*F3 + 20*G3) -> 60 | C3: =(0.5*H3 + 0.5*I3 + 0*J3 + 0*K3 + 0*L3) -> 0 | D3: =(0.5*M3 + 0.25*N3 + 0.25*O3 + 0*P3 + 0*Q3) -> 0 | E3: =(R3 + S3 + T3 + U3 + V3)/5 -> 1 | F3: =(W3 + X3 + Y3 +Z3 + AA3)/5 -> 1 | G3: =(AB3 + AC3 + AD3 +AE3 + AF3)/5 -> 1 | H3: 0 | I3: 0 | J3: 0 | K3: 0 | L3: 0 | M3: 0 | N3: 0 | O3: 0 | P3: 0 | Q3: 0 | R3: 1 | S3: 1 | T3: 1 | U3: 1 | V3: 1 | W3: 1 | X3: 1 | Y3: 1 | Z3: 1 | AA3: 1 | AB3: 1 | AC3: 1 | AD3: 1 | AE3: 1 | AF3: 1
A4: 1946659 | B4: =(15*C4 + 25*D4 + 25*E4 + 15*F4 + 20*G4) -> 87.5 | C4: =(0.5*H4 + 0.5*I4 + 0*J4 + 0*K4 + 0*L4) -> 1 | D4: =(0.5*M4 + 0.25*N4 + 0.25*O4 + 0*P4 + 0*Q4) -> 0.5 | E4: =(R4 + S4 + T4 + U4 + V4)/5 -> 1 | F4: =(W4 + X4 + Y4 +Z4 + AA4)/5 -> 1 | G4: =(AB4 + AC4 + AD4 +AE4 + AF4)/5 -> 1 | H4: 1 | I4: 1 | J4: 0 | K4: 0 | L4: 0 | M4: 0 | N4: 1 | O4: 1 | P4: 0 | Q4: 0 | R4: 1 | S4: 1 | T4: 1 | U4: 1 | V4: 1 | W4: 1 | X4: 1 | Y4: 1 | Z4: 1 | AA4: 1 | AB4: 1 | AC4: 1 | AD4: 1 | AE4: 1 | AF4: 1
A5: 1810132 | B5: =(15*C5 + 25*D5 + 25*E5 + 15*F5 + 20*G5) -> 31.25 | C5: =(0.5*H5 + 0.5*I5 + 0*J5 + 0*K5 + 0*L5) -> 0.5 | D5: =(0.5*M5 + 0.25*N5 + 0.25*O5 + 0*P5 + 0*Q5) -> 0.75 | E5: =(R5 + S5 + T5 + U5 + V5)/5 -> 0.2 | F5: =(W5 + X5 + Y5 +Z5 + AA5)/5 -> 0 | G5: =(AB5 + AC5 + AD5 +AE5 + AF5)/5 -> 0 | H5: 1 | I5: 0 | J5: 0 | K5: 0 | L5: 0 | M5: 0.5 | N5: 1 | O5: 1 | P5: 0 | Q5: 0 | R5: 1 | S5: 0 | T5: 0 | U5: 0 | V5: 0 | W5: 0 | X5: 0 | Y5: 0 | Z5: 0 | AA5: 0 | AB5: 0 | AC5: 0 | AD5: 0 | AE5: 0 | AF5: 0
A6: 2043199 | B6: =(15*C6 + 25*D6 + 25*E6 + 15*F6 + 20*G6) -> 40.5 | C6: =(0.5*H6 + 0.5*I6 + 0*J6 + 0*K6 + 0*L6) -> 1 | D6: =(0.5*M6 + 0.25*N6 + 0.25*O6 + 0*P6 + 0*Q6) -> 0.5 | E6: =(R6 + S6 + T6 + U6 + V6)/5 -> 0.4 | F6: =(W6 + X6 + Y6 +Z6 + AA6)/5 -> 0.2 | G6: =(AB6 + AC6 + AD6 +AE6 + AF6)/5 -> 0 | H6: 1 | I6: 1 | J6: 0 | K6: 0 | L6: 0 | M6: 0 | N6: 1 | O6: 1 | P6: 0 | Q6: 0 | R6: 1 | S6: 1 | T6: 0 | U6: 0 | V6: 0 | W6: 0 | X6: 1 | Y6: 0 | Z6: 0 | AA6: 0 | AB6: 0 | AC6: 0 | AD6: 0 | AE6: 0 | AF6: 0
A7: 1894899 | B7: =(15*C7 + 25*D7 + 25*E7 + 15*F7 + 20*G7) -> 10 | C7: =(0.5*H7 + 0.5*I7 + 0*J7 + 0*K7 + 0*L7) -> 0 | D7: =(0.5*M7 + 0.25*N7 + 0.25*O7 + 0*P7 + 0*Q7) -> 0 | E7: =(R7 + S7 + T7 + U7 + V7)/5 -> 0.4 | F7: =(W7 + X7 + Y7 +Z7 + AA7)/5 -> 0 | G7: =(AB7 + AC7 + AD7 +AE7 + AF7)/5 -> 0 | H7: 0 | I7: 0 | J7: 0 | K7: 0 | L7: 0 | M7: 0 | N7: 0 | O7: 0 | P7: 0 | Q7: 0 | R7: 1 | S7: 1 | T7: 0 | U7: 0 | V7: 0 | W7: 0 | X7: 0 | Y7: 0 | Z7: 0 | AA7: 0 | AB7: 0 | AC7: 0 | AD7: 0 | AE7: 0 | AF7: 0
A8: 2065850 | B8: =(15*C8 + 25*D8 + 25*E8 + 15*F8 + 20*G8) -> 37.5 | C8: =(0.5*H8 + 0.5*I8 + 0*J8 + 0*K8 + 0*L8) -> 1 | D8: =(0.5*M8 + 0.25*N8 + 0.25*O8 + 0*P8 + 0*Q8) -> 0.5 | E8: =(R8 + S8 + T8 + U8 + V8)/5 -> 0.4 | F8: =(W8 + X8 + Y8 +Z8 + AA8)/5 -> 0 | G8: =(AB8 + AC8 + AD8 +AE8 + AF8)/5 -> 0 | H8: 1 | I8: 1 | J8: 0 | K8: 0 | L8: 0 | M8: 0 | N8: 1 | O8: 1 | P8: 0 | Q8: 0 | R8: 1 | S8: 1 | T8: 0 | U8: 0 | V8: 0 | W8: 0 | X8: 0 | Y8: 0 | Z8: 0 | AA8: 0 | AB8: 0 | AC8: 0 | AD8: 0 | AE8: 0 | AF8: 0
A9: 2087336 | B9: =(15*C9 + 25*D9 + 25*E9 + 15*F9 + 20*G9) -> 32.5 | C9: =(0.5*H9 + 0.5*I9 + 0*J9 + 0*K9 + 0*L9) -> 0.5 | D9: =(0.5*M9 + 0.25*N9 + 0.25*O9 + 0*P9 + 0*Q9) -> 1 | E9: =(R9 + S9 + T9 + U9 + V9)/5 -> 0 | F9: =(W9 + X9 + Y9 +Z9 + AA9)/5 -> 0 | G9: =(AB9 + AC9 + AD9 +AE9 + AF9)/5 -> 0 | H9: 1 | I9: 0 | J9: 0 | K9: 0 | L9: 0 | M9: 1 | N9: 1 | O9: 1 | P9: 0 | Q9: 0 | R9: 0 | S9: 0 | T9: 0 | U9: 0 | V9: 0 | W9: 0 | X9: 0 | Y9: 0 | Z9: 0 | AA9: 0 | AB9: 0 | AC9: 0 | AD9: 0 | AE9: 0 | AF9: 0
A10: 2063098 | B10: =(15*C10 + 25*D10 + 25*E10 + 15*F10 + 20*G10) -> 87.5 | C10: =(0.5*H10 + 0.5*I10 + 0*J10 + 0*K10 + 0*L10) -> 1 | D10: =(0.5*M10 + 0.25*N10 + 0.25*O10 + 0*P10 + 0*Q10) -> 0.5 | E10: =(R10 + S10 + T10 + U10 + V10)/5 -> 1 | F10: =(W10 + X10 + Y10 +Z10 + AA10)/5 -> 1 | G10: =(AB10 + AC10 + AD10 +AE10 + AF10)/5 -> 1 | H10: 1 | I10: 1 | J10: 0 | K10: 0 | L10: 0 | M10: 0 | N10: 1 | O10: 1 | P10: 0 | Q10: 0 | R10: 1 | S10: 1 | T10: 1 | U10: 1 | V10: 1 | W10: 1 | X10: 1 | Y10: 1 | Z10: 1 | AA10: 1 | AB10: 1 | AC10: 1 | AD10: 1 | AE10: 1 | AF10: 1
A11: 2085060 | B11: =(15*C11 + 25*D11 + 25*E11 + 15*F11 + 20*G11) -> 75.5 | C11: =(0.5*H11 + 0.5*I11 + 0*J11 + 0*K11 + 0*L11) -> 1 | D11: =(0.5*M11 + 0.25*N11 + 0.25*O11 + 0*P11 + 0*Q11) -> 0.5 | E11: =(R11 + S11 + T11 + U11 + V11)/5 -> 1 | F11: =(W11 + X11 + Y11 +Z11 + AA11)/5 -> 0.2 | G11: =(AB11 + AC11 + AD11 +AE11 + AF11)/5 -> 1 | H11: 1 | I11: 1 | J11: 0 | K11: 0 | L11: 0 | M11: 0 | N11: 1 | O11: 1 | P11: 0 | Q11: 0 | R11: 1 | S11: 1 | T11: 1 | U11: 1 | V11: 1 | W11: 0 | X11: 0 | Y11: 1 | Z11: 0 | AA11: 0 | AB11: 1 | AC11: 1 | AD11: 1 | AE11: 1 | AF11: 1
A12: 1996623 | B12: =(15*C12 + 25*D12 + 25*E12 + 15*F12 + 20*G12) -> 20 | C12: =(0.5*H12 + 0.5*I12 + 0*J12 + 0*K12 + 0*L12) -> 0.5 | D12: =(0.5*M12 + 0.25*N12 + 0.25*O12 + 0*P12 + 0*Q12) -> 0.5 | E12: =(R12 + S12 + T12 + U12 + V12)/5 -> 0 | F12: =(W12 + X12 + Y12 +Z12 + AA12)/5 -> 0 | G12: =(AB12 + AC12 + AD12 +AE12 + AF12)/5 -> 0 | H12: 1 | I12: 0 | J12: 0 | K12: 0 | L12: 0 | M12: 0 | N12: 1 | O12: 1 | P12: 0 | Q12: 0 | R12: 0 | S12: 0 | T12: 0 | U12: 0 | V12: 0 | W12: 0 | X12: 0 | Y12: 0 | Z12: 0 | AA12: 0 | AB12: 0 | AC12: 0 | AD12: 0 | AE12: 0 | AF12: 0
A13: 1934929 | B13: =(15*C13 + 25*D13 + 25*E13 + 15*F13 + 20*G13) -> 20 | C13: =(0.5*H13 + 0.5*I13 + 0*J13 + 0*K13 + 0*L13) -> 1 | D13: =(0.5*M13 + 0.25*N13 + 0.25*O13 + 0*P13 + 0*Q13) -> 0 | E13: =(R13 + S13 + T13 + U13 + V13)/5 -> 0.2 | F13: =(W13 + X13 + Y13 +Z13 + AA13)/5 -> 0 | G13: =(AB13 + AC13 + AD13 +AE13 + AF13)/5 -> 0 | H13: 1 | I13: 1 | J13: 0 | K13: 0 | L13: 0 | M13: 0 | N13: 0 | O13: 0 | P13: 0 | Q13: 0 | R13: 1 | S13: 0 | T13: 0 | U13: 0 | V13: 0 | W13: 0 | X13: 0 | Y13: 0 | Z13: 0 | AA13: 0 | AB13: 0 | AC13: 0 | AD13: 0 | AE13: 0 | AF13: 0
A14: 2060444 | B14: =(15*C14 + 25*D14 + 25*E14 + 15*F14 + 20*G14) -> 0 | C14: =(0.5*H14 + 0.5*I14 + 0*J14 + 0*K14 + 0*L14) -> 0 | D14: =(0.5*M14 + 0.25*N14 + 0.25*O14 + 0*P14 + 0*Q14) -> 0 | E14: =(R14 + S14 + T14 + U14 + V14)/5 -> 0 | F14: =(W14 + X14 + Y14 +Z14 + AA14)/5 -> 0 | G14: =(AB14 + AC14 + AD14 +AE14 + AF14)/5 -> 0 | H14: 0 | I14: 0 | J14: 0 | K14: 0 | L14: 0 | M14: 0 | N14: 0 | O14: 0 | P14: 0 | Q14: 0 | R14: 0 | S14: 0 | T14: 0 | U14: 0 | V14: 0 | W14: 0 | X14: 0 | Y14: 0 | Z14: 0 | AA14: 0 | AB14: 0 | AC14: 0 | AD14: 0 | AE14: 0 | AF14: 0
... A28: 2047230 | B28: =(15*C28 + 25*D28 + 25*E28 + 15*F28 + 20*G28) -> 37.5 | C28: =(0.5*H28 + 0.5*I28 + 0*J28 + 0*K28 + 0*L28) -> 1 | D28: =(0.5*M28 + 0.25*N28 + 0.25*O28 + 0*P28 + 0*Q28) -> 0.5 | E28: =(R28 + S28 + T28 + U28 + V28)/5 -> 0.4 | F28: =(W28 + X28 + Y28 +Z28 + AA28)/5 -> 0 | G28: =(AB28 + AC28 + AD28 +AE28 + AF28)/5 -> 0 | H28: 1 | I28: 1 | J28: 0 | K28: 0 | L28: 0 | M28: 0 | N28: 1 | O28: 1 | P28: 0 | Q28: 0 | R28: 1 | S28: 1 | T28: 0 | U28: 0 | V28: 0 | W28: 0 | X28: 0 | Y28: 0 | Z28: 0 | AA28: 0 | AB28: 0 | AC28: 0 | AD28: 0 | AE28: 0 | AF28: 0
A30: Non valutabili causa errori formattazione:
A31: 1938314 | B31: Manca numero matricola nel nome del file zip.
A32: 2002583 | B32: Errore formattazione nome file zip: usato _ invece di -
A34: EX 1
A36: Test 1 | B36: Test 1: Increasing the number of drones (N) the collision rate increases
A37: Test 2 | B37: Test 2: Decreasing the Volume (L) the collision rate increases
A39: EX2
A40: Test 1 | B40: Collision rate must be less than that in exercise 1.
A41: Test 2 | B41: Increasing the number of drones (N) the collision rate increases
A42: Test 3 | B42: Decreasing the Volume (L) the collision rate increases

Sheet Sheet2
A1: SCORE | B1: CDF | G1: TOTAL
A2: =(Sheet1!B7) -> 10 | B2: =(1/$G$2) -> 0.016949153 | C2: =SUM($B2:$B$60) -> 1 | D2: 31 | E2: =_xlfn.IFS(C2 > 0.95, 31, C2 > 0.9, 30, C2 > 0.85, 29, C2 > 0.8, 27, C2 > 0.75, 26, C2 > 0.7, 25, C2 > 0.65, 24, C2 > 0.6 , 23, C2 > 0.55 , 22, C2 > 0.5, 21, C2 > 0.45, 20, C2 > 0.4, 19, C2 > 0.35, 18, C2 <= 0.35, 0 ) -> 31 | G2: 59
A3: =(#REF!) -> #REF! | B3: =(2/$G$2) -> 0.033898305 | C3: =SUM($B3:$B$60) -> 0.98305085 | D3: 31 | E3: =_xlfn.IFS(C3 > 0.95, 31, C3 > 0.9, 30, C3 > 0.85, 29, C3 > 0.8, 27, C3 > 0.75, 26, C3 > 0.7, 25, C3 > 0.65, 24, C3 > 0.6 , 23, C3 > 0.55 , 22, C3 > 0.5, 21, C3 > 0.45, 20, C3 > 0.4, 19, C3 > 0.35, 18, C3 <= 0.35, 0 ) -> 31
A4: =(#REF!) -> #REF! | E4: =_xlfn.IFS(C4 > 0.95, 31, C4 > 0.9, 30, C4 > 0.85, 29, C4 > 0.8, 27, C4 > 0.75, 26, C4 > 0.7, 25, C4 > 0.65, 24, C4 > 0.6 , 23, C4 > 0.55 , 22, C4 > 0.5, 21, C4 > 0.45, 20, C4 > 0.4, 19, C4 > 0.35, 18, C4 <= 0.35, 0 ) -> 0
A5: =(#REF!) -> #REF! | B5: =(1/$G$2) -> 0.016949153 | C5: =SUM($B5:$B$60) -> 0.94915254 | D5: 30 | E5: =_xlfn.IFS(C5 > 0.95, 31, C5 > 0.9, 30, C5 > 0.85, 29, C5 > 0.8, 27, C5 > 0.75, 26, C5 > 0.7, 25, C5 > 0.65, 24, C5 > 0.6 , 23, C5 > 0.55 , 22, C5 > 0.5, 21, C5 > 0.45, 20, C5 > 0.4, 19, C5 > 0.35, 18, C5 <= 0.35, 0 ) -> 30
A6: =(Sheet1!B8) -> 37.5 | B6: =(2/$G$2) -> 0.033898305 | C6: =SUM($B6:$B$60) -> 0.93220339 | D6: 30 | E6: =_xlfn.IFS(C6 > 0.95, 31, C6 > 0.9, 30, C6 > 0.85, 29, C6 > 0.8, 27, C6 > 0.75, 26, C6 > 0.7, 25, C6 > 0.65, 24, C6 > 0.6 , 23, C6 > 0.55 , 22, C6 > 0.5, 21, C6 > 0.45, 20, C6 > 0.4, 19, C6 > 0.35, 18, C6 <= 0.35, 0 ) -> 30
A7: =(Sheet1!B17) -> 58 | E7: =_xlfn.IFS(C7 > 0.95, 31, C7 > 0.9, 30, C7 > 0.85, 29, C7 > 0.8, 27, C7 > 0.75, 26, C7 > 0.7, 25, C7 > 0.65, 24, C7 > 0.6 , 23, C7 > 0.55 , 22, C7 > 0.5, 21, C7 > 0.45, 20, C7 > 0.4, 19, C7 > 0.35, 18, C7 <= 0.35, 0 ) -> 0
A8: =(Sheet1!B21) -> 0 | B8: =(2/$G$2) -> 0.033898305 | C8: =SUM($B8:$B$60) -> 0.89830508 | D8: 29 | E8: =_xlfn.IFS(C8 > 0.95, 31, C8 > 0.9, 30, C8 > 0.85, 29, C8 > 0.8, 27, C8 > 0.75, 26, C8 > 0.7, 25, C8 > 0.65, 24, C8 > 0.6 , 23, C8 > 0.55 , 22, C8 > 0.5, 21, C8 > 0.45, 20, C8 > 0.4, 19, C8 > 0.35, 18, C8 <= 0.35, 0 ) -> 29
A9: =(#REF!) -> #REF! | E9: =_xlfn.IFS(C9 > 0.95, 31, C9 > 0.9, 30, C9 > 0.85, 29, C9 > 0.8, 27, C9 > 0.75, 26, C9 > 0.7, 25, C9 > 0.65, 24, C9 > 0.6 , 23, C9 > 0.55 , 22, C9 > 0.5, 21, C9 > 0.45, 20, C9 > 0.4, 19, C9 > 0.35, 18, C9 <= 0.35, 0 ) -> 0
A10: =(Sheet1!B26) -> 87.5 | B10: =(3/$G$2) -> 0.050847458 | C10: =SUM($B10:$B$60) -> 0.86440678 | D10: 29 | E10: =_xlfn.IFS(C10 > 0.95, 31, C10 > 0.9, 30, C10 > 0.85, 29, C10 > 0.8, 27, C10 > 0.75, 26, C10 > 0.7, 25, C10 > 0.65, 24, C10 > 0.6 , 23, C10 > 0.55 , 22, C10 > 0.5, 21, C10 > 0.45, 20, C10 > 0.4, 19, C10 > 0.35, 18, C10 <= 0.35, 0 ) -> 29
A11: =(#REF!) -> #REF! | E11: =_xlfn.IFS(C11 > 0.95, 31, C11 > 0.9, 30, C11 > 0.85, 29, C11 > 0.8, 27, C11 > 0.75, 26, C11 > 0.7, 25, C11 > 0.65, 24, C11 > 0.6 , 23, C11 > 0.55 , 22, C11 > 0.5, 21, C11 > 0.45, 20, C11 > 0.4, 19, C11 > 0.35, 18, C11 <= 0.35, 0 ) -> 0
A12: =(#REF!) -> #REF! | E12: =_xlfn.IFS(C12 > 0.95, 31, C12 > 0.9, 30, C12 > 0.85, 29, C12 > 0.8, 27, C12 > 0.75, 26, C12 > 0.7, 25, C12 > 0.65, 24, C12 > 0.6 , 23, C12 > 0.55 , 22, C12 > 0.5, 21, C12 > 0.45, 20, C12 > 0.4, 19, C12 > 0.35, 18, C12 <= 0.35, 0 ) -> 0
A13: =(Sheet1!B6) -> 40.5 | B13: =(2/$G$2) -> 0.033898305 | C13: =SUM($B13:$B$60) -> 0.81355932 | D13: 28 | E13: =_xlfn.IFS(C13 > 0.95, 31, C13 > 0.9, 30, C13 > 0.85, 29, C13 > 0.8, 27, C13 > 0.75, 26, C13 > 0.7, 25, C13 > 0.65, 24, C13 > 0.6 , 23, C13 > 0.55 , 22, C13 > 0.5, 21, C13 > 0.45, 20, C13 > 0.4, 19, C13 > 0.35, 18, C13 <= 0.35, 0 ) -> 27
A14: =(#REF!) -> #REF! | E14: =_xlfn.IFS(C14 > 0.95, 31, C14 > 0.9, 30, C14 > 0.85, 29, C14 > 0.8, 27, C14 > 0.75, 26, C14 > 0.7, 25, C14 > 0.65, 24, C14 > 0.6 , 23, C14 > 0.55 , 22, C14 > 0.5, 21, C14 > 0.45, 20, C14 > 0.4, 19, C14 > 0.35, 18, C14 <= 0.35, 0 ) -> 0
A15: =(#REF!) -> #REF! | B15: =(1/$G$2) -> 0.016949153 | C15: =SUM($B15:$B$60) -> 0.77966102 | D15: 27 | E15: =_xlfn.IFS(C15 > 0.95, 31, C15 > 0.9, 30, C15 > 0.85, 29, C15 > 0.8, 27, C15 > 0.75, 26, C15 > 0.7, 25, C15 > 0.65, 24, C15 > 0.6 , 23, C15 > 0.55 , 22, C15 > 0.5, 21, C15 > 0.45, 20, C15 > 0.4, 19, C15 > 0.35, 18, C15 <= 0.35, 0 ) -> 26
A16: =(#REF!) -> #REF! | B16: =(1/$G$2) -> 0.016949153 | C16: =SUM($B16:$B$60) -> 0.76271186 | D16: 27 | E16: =_xlfn.IFS(C16 > 0.95, 31, C16 > 0.9, 30, C16 > 0.85, 29, C16 > 0.8, 27, C16 > 0.75, 26, C16 > 0.7, 25, C16 > 0.65, 24, C16 > 0.6 , 23, C16 > 0.55 , 22, C16 > 0.5, 21, C16 > 0.45, 20, C16 > 0.4, 19, C16 > 0.35, 18, C16 <= 0.35, 0 ) -> 26
A17: =(Sheet1!B16) -> 75.5 | B17: =(4/$G$2) -> 0.06779661 | C17: =SUM($B17:$B$60) -> 0.74576271 | D17: 26 | E17: =_xlfn.IFS(C17 > 0.95, 31, C17 > 0.9, 30, C17 > 0.85, 29, C17 > 0.8, 27, C17 > 0.75, 26, C17 > 0.7, 25, C17 > 0.65, 24, C17 > 0.6 , 23, C17 > 0.55 , 22, C17 > 0.5, 21, C17 > 0.45, 20, C17 > 0.4, 19, C17 > 0.35, 18, C17 <= 0.35, 0 ) -> 25
A18: =(#REF!) -> #REF! | E18: =_xlfn.IFS(C18 > 0.95, 31, C18 > 0.9, 30, C18 > 0.85, 29, C18 > 0.8, 27, C18 > 0.75, 26, C18 > 0.7, 25, C18 > 0.65, 24, C18 > 0.6 , 23, C18 > 0.55 , 22, C18 > 0.5, 21, C18 > 0.45, 20, C18 > 0.4, 19, C18 > 0.35, 18, C18 <= 0.35, 0 ) -> 0
A19: =(#REF!) -> #REF! | E19: =_xlfn.IFS(C19 > 0.95, 31, C19 > 0.9, 30, C19 > 0.85, 29, C19 > 0.8, 27, C19 > 0.75, 26, C19 > 0.7, 25, C19 > 0.65, 24, C19 > 0.6 , 23, C19 > 0.55 , 22, C19 > 0.5, 21, C19 > 0.45, 20, C19 > 0.4, 19, C19 > 0.35, 18, C19 <= 0.35, 0 ) -> 0
A20: =(#REF!) -> #REF! | E20: =_xlfn.IFS(C20 > 0.95, 31, C20 > 0.9, 30, C20 > 0.85, 29, C20 > 0.8, 27, C20 > 0.75, 26, C20 > 0.7, 25, C20 > 0.65, 24, C20 > 0.6 , 23, C20 > 0.55 , 22, C20 > 0.5, 21, C20 > 0.45, 20, C20 > 0.4, 19, C20 > 0.35, 18, C20 <= 0.35, 0 ) -> 0
A21: =(Sheet1!B10) -> 87.5 | B21: =(3/$G$2) -> 0.050847458 | C21: =SUM($B21:$B$60) -> 0.6779661 | D21: 25 | E21: =_xlfn.IFS(C21 > 0.95, 31, C21 > 0.9, 30, C21 > 0.85, 29, C21 > 0.8, 27, C21 > 0.75, 26, C21 > 0.7, 25, C21 > 0.65, 24, C21 > 0.6 , 23, C21 > 0.55 , 22, C21 > 0.5, 21, C21 > 0.45, 20, C21 > 0.4, 19, C21 > 0.35, 18, C21 <= 0.35, 0 ) -> 24
A22: =(#REF!) -> #REF! | E22: =_xlfn.IFS(C22 > 0.95, 31, C22 > 0.9, 30, C22 > 0.85, 29, C22 > 0.8, 27, C22 > 0.75, 26, C22 > 0.7, 25, C22 > 0.65, 24, C22 > 0.6 , 23, C22 > 0.55 , 22, C22 > 0.5, 21, C22 > 0.45, 20, C22 > 0.4, 19, C22 > 0.35, 18, C22 <= 0.35, 0 ) -> 0
A23: =(#REF!) -> #REF! | E23: =_xlfn.IFS(C23 > 0.95, 31, C23 > 0.9, 30, C23 > 0.85, 29, C23 > 0.8, 27, C23 > 0.75, 26, C23 > 0.7, 25, C23 > 0.65, 24, C23 > 0.6 , 23, C23 > 0.55 , 22, C23 > 0.5, 21, C23 > 0.45, 20, C23 > 0.4, 19, C23 > 0.35, 18, C23 <= 0.35, 0 ) -> 0
A24: =(#REF!) -> #REF! | B24: =(1/$G$2) -> 0.016949153 | C24: =SUM($B24:$B$60) -> 0.62711864 | D24: 24 | E24: =_xlfn.IFS(C24 > 0.95, 31, C24 > 0.9, 30, C24 > 0.85, 29, C24 > 0.8, 27, C24 > 0.75, 26, C24 > 0.7, 25, C24 > 0.65, 24, C24 > 0.6 , 23, C24 > 0.55 , 22, C24 > 0.5, 21, C24 > 0.45, 20, C24 > 0.4, 19, C24 > 0.35, 18, C24 <= 0.35, 0 ) -> 23
A25: =(Sheet1!B13) -> 20 | B25: =(2/$G$2) -> 0.033898305 | C25: =SUM($B25:$B$60) -> 0.61016949 | D25: 24 | E25: =_xlfn.IFS(C25 > 0.95, 31, C25 > 0.9, 30, C25 > 0.85, 29, C25 > 0.8, 27, C25 > 0.75, 26, C25 > 0.7, 25, C25 > 0.65, 24, C25 > 0.6 , 23, C25 > 0.55 , 22, C25 > 0.5, 21, C25 > 0.45, 20, C25 > 0.4, 19, C25 > 0.35, 18, C25 <= 0.35, 0 ) -> 23
A26: =(Sheet1!B18) -> 81.75 | E26: =_xlfn.IFS(C26 > 0.95, 31, C26 > 0.9, 30, C26 > 0.85, 29, C26 > 0.8, 27, C26 > 0.75, 26, C26 > 0.7, 25, C26 > 0.65, 24, C26 > 0.6 , 23, C26 > 0.55 , 22, C26 > 0.5, 21, C26 > 0.45, 20, C26 > 0.4, 19, C26 > 0.35, 18, C26 <= 0.35, 0 ) -> 0
A27: =(#REF!) -> #REF! | B27: =(2/$G$2) -> 0.033898305 | C27: =SUM($B27:$B$60) -> 0.57627119 | D27: 23 | E27: =_xlfn.IFS(C27 > 0.95, 31, C27 > 0.9, 30, C27 > 0.85, 29, C27 > 0.8, 27, C27 > 0.75, 26, C27 > 0.7, 25, C27 > 0.65, 24, C27 > 0.6 , 23, C27 > 0.55 , 22, C27 > 0.5, 21, C27 > 0.45, 20, C27 > 0.4, 19, C27 > 0.35, 18, C27 <= 0.35, 0 ) -> 22
A28: =(#REF!) -> #REF! | E28: =_xlfn.IFS(C28 > 0.95, 31, C28 > 0.9, 30, C28 > 0.85, 29, C28 > 0.8, 27, C28 > 0.75, 26, C28 > 0.7, 25, C28 > 0.65, 24, C28 > 0.6 , 23, C28 > 0.55 , 22, C28 > 0.5, 21, C28 > 0.45, 20, C28 > 0.4, 19, C28 > 0.35, 18, C28 <= 0.35, 0 ) -> 0
A29: =(Sheet1!B9) -> 32.5 | B29: =(7/$G$2) -> 0.11864407 | C29: =SUM($B29:$B$60) -> 0.54237288 | D29: 22 | E29: =_xlfn.IFS(C29 > 0.95, 31, C29 > 0.9, 30, C29 > 0.85, 29, C29 > 0.8, 27, C29 > 0.75, 26, C29 > 0.7, 25, C29 > 0.65, 24, C29 > 0.6 , 23, C29 > 0.55 , 22, C29 > 0.5, 21, C29 > 0.45, 20, C29 > 0.4, 19, C29 > 0.35, 18, C29 <= 0.35, 0 ) -> 21
A30: =(Sheet1!B20) -> 20 | E30: =_xlfn.IFS(C30 > 0.95, 31, C30 > 0.9, 30, C30 > 0.85, 29, C30 > 0.8, 27, C30 > 0.75, 26, C30 > 0.7, 25, C30 > 0.65, 24, C30 > 0.6 , 23, C30 > 0.55 , 22, C30 > 0.5, 21, C30 > 0.45, 20, C30 > 0.4, 19, C30 > 0.35, 18, C30 <= 0.35, 0 ) -> 0
A31: =(Sheet1!B22) -> 33.75 | E31: =_xlfn.IFS(C31 > 0.95, 31, C31 > 0.9, 30, C31 > 0.85, 29, C31 > 0.8, 27, C31 > 0.75, 26, C31 > 0.7, 25, C31 > 0.65, 24, C31 > 0.6 , 23, C31 > 0.55 , 22, C31 > 0.5, 21, C31 > 0.45, 20, C31 > 0.4, 19, C31 > 0.35, 18, C31 <= 0.35, 0 ) -> 0
A32: =(Sheet1!B23) -> 37.5 | E32: =_xlfn.IFS(C32 > 0.95, 31, C32 > 0.9, 30, C32 > 0.85, 29, C32 > 0.8, 27, C32 > 0.75, 26, C32 > 0.7, 25, C32 > 0.65, 24, C32 > 0.6 , 23, C32 > 0.55 , 22, C32 > 0.5, 21, C32 > 0.45, 20, C32 > 0.4, 19, C32 > 0.35, 18, C32 <= 0.35, 0 ) -> 0
A33: =(Sheet1!B28) -> 37.5 | E33: =_xlfn.IFS(C33 > 0.95, 31, C33 > 0.9, 30, C33 > 0.85, 29, C33 > 0.8, 27, C33 > 0.75, 26, C33 > 0.7, 25, C33 > 0.65, 24, C33 > 0.6 , 23, C33 > 0.55 , 22, C33 > 0.5, 21, C33 > 0.45, 20, C33 > 0.4, 19, C33 > 0.35, 18, C33 <= 0.35, 0 ) -> 0
A34: =(#REF!) -> #REF! | E34: =_xlfn.IFS(C34 > 0.95, 31, C34 > 0.9, 30, C34 > 0.85, 29, C34 > 0.8, 27, C34 > 0.75, 26, C34 > 0.7, 25, C34 > 0.65, 24, C34 > 0.6 , 23, C34 > 0.55 , 22, C34 > 0.5, 21, C34 > 0.45, 20, C34 > 0.4, 19, C34 > 0.35, 18, C34 <= 0.35, 0 ) -> 0
A35: =(#REF!) -> #REF! | E35: =_xlfn.IFS(C35 > 0.95, 31, C35 > 0.9, 30, C35 > 0.85, 29, C35 > 0.8, 27, C35 > 0.75, 26, C35 > 0.7, 25, C35 > 0.65, 24, C35 > 0.6 , 23, C35 > 0.55 , 22, C35 > 0.5, 21, C35 > 0.45, 20, C35 > 0.4, 19, C35 > 0.35, 18, C35 <= 0.35, 0 ) -> 0
A36: =(Sheet1!B24) -> 76.5 | B36: =(4/$G$2) -> 0.06779661 | C36: =SUM($B36:$B$60) -> 0.42372881 | D36: 20 | E36: =_xlfn.IFS(C36 > 0.95, 31, C36 > 0.9, 30, C36 > 0.85, 29, C36 > 0.8, 27, C36 > 0.75, 26, C36 > 0.7, 25, C36 > 0.65, 24, C36 > 0.6 , 23, C36 > 0.55 , 22, C36 > 0.5, 21, C36 > 0.45, 20, C36 > 0.4, 19, C36 > 0.35, 18, C36 <= 0.35, 0 ) -> 19
A37: =(Sheet1!B27) -> 46.875 | E37: =_xlfn.IFS(C37 > 0.95, 31, C37 > 0.9, 30, C37 > 0.85, 29, C37 > 0.8, 27, C37 > 0.75, 26, C37 > 0.7, 25, C37 > 0.65, 24, C37 > 0.6 , 23, C37 > 0.55 , 22, C37 > 0.5, 21, C37 > 0.45, 20, C37 > 0.4, 19, C37 > 0.35, 18, C37 <= 0.35, 0 ) -> 0
A38: =(#REF!) -> #REF! | E38: =_xlfn.IFS(C38 > 0.95, 31, C38 > 0.9, 30, C38 > 0.85, 29, C38 > 0.8, 27, C38 > 0.75, 26, C38 > 0.7, 25, C38 > 0.65, 24, C38 > 0.6 , 23, C38 > 0.55 , 22, C38 > 0.5, 21, C38 > 0.45, 20, C38 > 0.4, 19, C38 > 0.35, 18, C38 <= 0.35, 0 ) -> 0
A39: =(#REF!) -> #REF! | E39: =_xlfn.IFS(C39 > 0.95, 31, C39 > 0.9, 30, C39 > 0.85, 29, C39 > 0.8, 27, C39 > 0.75, 26, C39 > 0.7, 25, C39 > 0.65, 24, C39 > 0.6 , 23, C39 > 0.55 , 22, C39 > 0.5, 21, C39 > 0.45, 20, C39 > 0.4, 19, C39 > 0.35, 18, C39 <= 0.35, 0 ) -> 0
A40: =(Sheet1!B5) -> 31.25 | B40: =(2/$G$2) -> 0.033898305 | C40: =SUM($B40:$B$60) -> 0.3559322 | D40: 18 | E40: =_xlfn.IFS(C40 > 0.95, 31, C40 > 0.9, 30, C40 > 0.85, 29, C40 > 0.8, 27, C40 > 0.75, 26, C40 > 0.7, 25, C40 > 0.65, 24, C40 > 0.6 , 23, C40 > 0.55 , 22, C40 > 0.5, 21, C40 > 0.45, 20, C40 > 0.4, 19, C40 > 0.35, 18, C40 <= 0.35, 0 ) -> 18
...

Sheet Sheet3
A1: From | B1: To | C1: Grade
A2: 0.95 | B2: 1 | C2: 31
A3: 0.9 | B3: 0.95 | C3: =(C2 -1) -> 30
A4: 0.85 | B4: 0.9 | C4: =(C3 -1) -> 29
A5: 0.8 | B5: 0.85 | C5: =(C4 -1) -> 28
A6: 0.75 | B6: 0.8 | C6: =(C5 -1) -> 27
A7: 0.7 | B7: 0.75 | C7: =(C6 -1) -> 26
A8: 0.65 | B8: 0.7 | C8: =(C7 -1) -> 25
A9: 0.6 | B9: 0.65 | C9: =(C8 -1) -> 24
A10: 0.55 | B10: 0.6 | C10: =(C9 -1) -> 23
A11: 0.5 | B11: 0.55 | C11: =(C10 -1) -> 22
A12: 0.45 | B12: 0.5 | C12: =(C11 -1) -> 21
A13: 0.4 | B13: 0.45 | C13: =(C12 -1) -> 20
A14: 0.35 | B14: 0.4 | C14: =(C13 -1) -> 19
A15: 0.3 | B15: 0.35 | C15: =(C14 -1) -> 18
A16: 0 | B16: 0.3 | C16: 0

Sheet ex-2025-02-25
A2: Matricola | B2: SCORE
A3: 2046542 | B3: 20
A4: 2041850 | B4: 100
A5: 2083154 | B5: 100
A6: 1760206 | B6: 22
A7: 2047604 | B7: 64
A8: 2045899 | B8: 20
A9: 1810132 | B9: 0
A10: 2047145 | B10: 44
A11: 2015518 | B11: 10
A12: 2050059 | B12: 82
A13: 2066344 | B13: 0
A14: 1888625 | B14: 54
... A45: 1884742 | B45: 20.8

Sheet ex-2025-03-21
A2: Matricola | B2: SCORE
A3: 2068261 | B3: 0
A4: 2045899 | B4: 12
A5: 1948382 | B5: 56
A6: 2047145 | B6: 88
A7: 2045204 | B7: 72
A8: 2015518 | B8: 20
A9: 1991139 | B9: 36
A10: 1933763 | B10: 0
A11: 1894899 | B11: 8
A12: 2087530 | B12: 28
A13: 2049029 | B13: 10
A14: 2059802 | B14: 0
... A61: 1884714 | B61: 80
